[2021-12-26 18:30:55,109] {taskinstance.py:670} INFO - Dependencies all met for <TaskInstance: twitter_dag.twitter_aluraonline 2021-12-21T09:00:00+00:00 [queued]>
[2021-12-26 18:30:55,129] {taskinstance.py:670} INFO - Dependencies all met for <TaskInstance: twitter_dag.twitter_aluraonline 2021-12-21T09:00:00+00:00 [queued]>
[2021-12-26 18:30:55,129] {taskinstance.py:880} INFO - 
--------------------------------------------------------------------------------
[2021-12-26 18:30:55,129] {taskinstance.py:881} INFO - Starting attempt 1 of 1
[2021-12-26 18:30:55,130] {taskinstance.py:882} INFO - 
--------------------------------------------------------------------------------
[2021-12-26 18:30:55,150] {taskinstance.py:901} INFO - Executing <Task(TwitterOperator): twitter_aluraonline> on 2021-12-21T09:00:00+00:00
[2021-12-26 18:30:55,152] {standard_task_runner.py:54} INFO - Started process 32326 to run task
[2021-12-26 18:30:55,188] {standard_task_runner.py:77} INFO - Running: ['airflow', 'run', 'twitter_dag', 'twitter_aluraonline', '2021-12-21T09:00:00+00:00', '--job_id', '4', '--pool', 'default_pool', '--raw', '-sd', 'DAGS_FOLDER/twitter_dag.py', '--cfg_path', '/tmp/tmpmvqxakz5']
[2021-12-26 18:30:55,189] {standard_task_runner.py:78} INFO - Job 4: Subtask twitter_aluraonline
[2021-12-26 18:30:55,215] {logging_mixin.py:112} INFO - Running <TaskInstance: twitter_dag.twitter_aluraonline 2021-12-21T09:00:00+00:00 [running]> on host note-cristian-agriness
[2021-12-26 18:30:55,226] {taskinstance.py:1150} ERROR - [Errno 13] Permission denied: '/Data_Science'
Traceback (most recent call last):
  File "/usr/local/lib/python3.6/pathlib.py", line 1231, in mkdir
    self._accessor.mkdir(self, mode)
  File "/usr/local/lib/python3.6/pathlib.py", line 388, in wrapped
    return strfunc(str(pathobj), *args)
FileNotFoundError: [Errno 2] No such file or directory: '/Data_Science/Projects/datapipeline/datalake/bronze/twitter_aluraonile/extract_date=2021-12-21'

During handling of the above exception, another exception occurred:

Traceback (most recent call last):
  File "/usr/local/lib/python3.6/pathlib.py", line 1231, in mkdir
    self._accessor.mkdir(self, mode)
  File "/usr/local/lib/python3.6/pathlib.py", line 388, in wrapped
    return strfunc(str(pathobj), *args)
FileNotFoundError: [Errno 2] No such file or directory: '/Data_Science/Projects/datapipeline/datalake/bronze/twitter_aluraonile'

During handling of the above exception, another exception occurred:

Traceback (most recent call last):
  File "/usr/local/lib/python3.6/pathlib.py", line 1231, in mkdir
    self._accessor.mkdir(self, mode)
  File "/usr/local/lib/python3.6/pathlib.py", line 388, in wrapped
    return strfunc(str(pathobj), *args)
FileNotFoundError: [Errno 2] No such file or directory: '/Data_Science/Projects/datapipeline/datalake/bronze'

During handling of the above exception, another exception occurred:

Traceback (most recent call last):
  File "/usr/local/lib/python3.6/pathlib.py", line 1231, in mkdir
    self._accessor.mkdir(self, mode)
  File "/usr/local/lib/python3.6/pathlib.py", line 388, in wrapped
    return strfunc(str(pathobj), *args)
FileNotFoundError: [Errno 2] No such file or directory: '/Data_Science/Projects/datapipeline/datalake'

During handling of the above exception, another exception occurred:

Traceback (most recent call last):
  File "/usr/local/lib/python3.6/pathlib.py", line 1231, in mkdir
    self._accessor.mkdir(self, mode)
  File "/usr/local/lib/python3.6/pathlib.py", line 388, in wrapped
    return strfunc(str(pathobj), *args)
FileNotFoundError: [Errno 2] No such file or directory: '/Data_Science/Projects/datapipeline'

During handling of the above exception, another exception occurred:

Traceback (most recent call last):
  File "/usr/local/lib/python3.6/pathlib.py", line 1231, in mkdir
    self._accessor.mkdir(self, mode)
  File "/usr/local/lib/python3.6/pathlib.py", line 388, in wrapped
    return strfunc(str(pathobj), *args)
FileNotFoundError: [Errno 2] No such file or directory: '/Data_Science/Projects'

During handling of the above exception, another exception occurred:

Traceback (most recent call last):
  File "/home/cristian/Desktop/datapipeline/.env/lib/python3.6/site-packages/airflow/models/taskinstance.py", line 984, in _run_raw_task
    result = task_copy.execute(context=context)
  File "/home/cristian/Desktop/Data_Science/Projects/datapipeline/airflow/plugins/operators/twitter_operator.py", line 52, in execute
    self.create_parent_folder()
  File "/home/cristian/Desktop/Data_Science/Projects/datapipeline/airflow/plugins/operators/twitter_operator.py", line 42, in create_parent_folder
    Path(Path(self.file_path).parent).mkdir(parents=True, exist_ok=True)
  File "/usr/local/lib/python3.6/pathlib.py", line 1238, in mkdir
    self.parent.mkdir(parents=True)
  File "/usr/local/lib/python3.6/pathlib.py", line 1238, in mkdir
    self.parent.mkdir(parents=True)
  File "/usr/local/lib/python3.6/pathlib.py", line 1238, in mkdir
    self.parent.mkdir(parents=True)
  [Previous line repeated 2 more times]
  File "/usr/local/lib/python3.6/pathlib.py", line 1231, in mkdir
    self._accessor.mkdir(self, mode)
  File "/usr/local/lib/python3.6/pathlib.py", line 388, in wrapped
    return strfunc(str(pathobj), *args)
PermissionError: [Errno 13] Permission denied: '/Data_Science'
[2021-12-26 18:30:55,227] {taskinstance.py:1194} INFO - Marking task as FAILED. dag_id=twitter_dag, task_id=twitter_aluraonline, execution_date=20211221T090000, start_date=20211226T213055, end_date=20211226T213055
[2021-12-26 18:31:00,077] {local_task_job.py:102} INFO - Task exited with return code 1
